Workbook

Sheet Delivery Stops
A1: Stop_ID | B1: Customer_Name | C1: Address | D1: Demand_kg | E1: Earliest_Delivery | F1: Latest_Delivery | G1: Service_Time_min
A2: 1 | B2: Pet Hospital | C2: 1510 Pine Rd | D2: 204 | E2: 08:30 | F2: 18:15 | G2: 29
A3: 2 | B3: Community Pharmacy | C3: 9532 Willow Dr | D3: 240 | E3: 12:30 | F3: 18:30 | G3: 11
A4: 3 | B4: Redstone Medical Center | C4: 5974 School Rd | D4: 183 | E4: 12:45 | F4: 17:15 | G4: 17
A5: 4 | B5: Furniture Warehouse | C5: 400 Aspen Ct | D5: 186 | E5: 08:15 | F5: 14:15 | G5: 24
A6: 5 | B6: Construction Supply | C6: 8617 Fourth St | D6: 201 | E6: 11:45 | F6: 14:45 | G6: 30
A7: 6 | B7: Farm Supply | C7: 4104 River Rd | D7: 162 | E7: 13:30 | F7: 18:45 | G7: 21
A8: 7 | B8: Fish Market | C8: 7490 River Rd | D8: 133 | E8: 11:15 | F8: 17:45 | G8: 19
A9: 8 | B9: Swimming Pool Supply | C9: 8271 Sunrise Blvd | D9: 285 | E9: 14:45 | F9: 18:45 | G9: 26
A10: 9 | B10: Dry Cleaners | C10: 1244 Second St | D10: 24 | E10: 09:00 | F10: 11:30 | G10: 28
A11: 10 | B11: Furniture Warehouse | C11: 1751 Valley Rd | D11: 89 | E11: 10:15 | F11: 12:45 | G11: 11
A12: 11 | B12: Pet Hospital | C12: 5946 Fourth St | D12: 108 | E12: 09:00 | F12: 11:00 | G12: 10
A13: 12 | B13: Tech Solutions Inc | C13: 356 Fourth St | D13: 150 | E13: 08:15 | F13: 13:00 | G13: 22
... A29: 28 | B29: Food Bank | C29: 717 River Rd | D29: 168 | E29: 11:45 | F29: 14:30 | G29: 25

Sheet Vehicle Fleet
A1: Vehicle_ID | B1: Type | C1: Capacity_kg | D1: Cost_per_mile | E1: Fixed_Daily_Cost | F1: Available_From | G1: Available_Until
A2: 1 | B2: Small Van | C2: 600 | D2: 0.5 | E2: 85 | F2: 06:00 | G2: 20:00
A3: 2 | B3: Small Van | C3: 600 | D3: 0.5 | E3: 85 | F3: 06:00 | G3: 20:00
A4: 3 | B4: Medium Truck | C4: 1400 | D4: 0.8 | E4: 130 | F4: 06:00 | G4: 20:00
A5: 4 | B5: Medium Truck | C5: 1400 | D5: 0.8 | E5: 130 | F5: 06:00 | G5: 20:00
A6: 5 | B6: Large Truck | C6: 2800 | D6: 1.2 | E6: 200 | F6: 06:00 | G6: 20:00

Sheet Depot
A1: Depot_ID | B1: Name | C1: Open_Time | D1: Close_Time
A2: DEPOT-001 | B2: Redstone County Central Depot | C2: 06:00 | D2: 20:00

Sheet Distance Matrix (miles)
B1: Depot | C1: Stop 1 | D1: Stop 2 | E1: Stop 3 | F1: Stop 4 | G1: Stop 5 | H1: Stop 6 | I1: Stop 7 | J1: Stop 8 | K1: Stop 9 | L1: Stop 10 | M1: Stop 11 | N1: Stop 12 | O1: Stop 13 | P1: Stop 14 | Q1: Stop 15 | R1: Stop 16 | S1: Stop 17 | T1: Stop 18 | U1: Stop 19 | V1: Stop 20 | W1: Stop 21 | X1: Stop 22 | Y1: Stop 23 | Z1: Stop 24 | AA1: Stop 25 | AB1: Stop 26 | AC1: Stop 27 | AD1: Stop 28
A2: Depot | B2: 0 | C2: 24.68 | D2: 2.8 | E2: 19.3 | F2: 8.46 | G2: 16.04 | H2: 4.67 | I2: 10.63 | J2: 25.87 | K2: 14.44 | L2: 7.45 | M2: 1.35 | N2: 8.72 | O2: 23.26 | P2: 14.86 | Q2: 1.25 | R2: 4.12 | S2: 25.97 | T2: 5.26 | U2: 20.84 | V2: 23.63 | W2: 20.67 | X2: 25.53 | Y2: 4.74 | Z2: 18.78 | AA2: 14.09 | AB2: 24.09 | AC2: 21.73 | AD2: 23.04
A3: Stop 1 | B3: 24.68 | C3: 0 | D3: 22.47 | E3: 17 | F3: 27.84 | G3: 36.49 | H3: 28.17 | I3: 35.21 | J3: 33.79 | K3: 10.26 | L3: 32.11 | M3: 23.5 | N3: 33.39 | O3: 46.57 | P3: 38.65 | Q3: 24.94 | R3: 27.64 | S3: 49.91 | T3: 26.23 | U3: 9.63 | V3: 30.99 | W3: 26.06 | X3: 47.62 | Y3: 19.94 | Z3: 26.2 | AA3: 38.77 | AB3: 48.49 | AC3: 45.95 | AD3: 45.27
A4: Stop 2 | B4: 2.8 | C4: 22.47 | D4: 0 | E4: 18.99 | F4: 10.74 | G4: 18.72 | H4: 7.45 | I4: 12.75 | J4: 27.38 | K4: 12.38 | L4: 9.76 | M4: 1.48 | N4: 11.18 | O4: 24.64 | P4: 17.62 | Q4: 2.53 | R4: 5.24 | S4: 28.66 | T4: 7.57 | U4: 19.53 | V4: 24.99 | W4: 21.59 | X4: 26.48 | Y4: 2.88 | Z4: 19.86 | AA4: 16.49 | AB4: 26.68 | AC4: 24.38 | AD4: 24.01
A5: Stop 3 | B5: 19.3 | C5: 17 | D5: 18.99 | E5: 0 | F5: 16.71 | G5: 23.46 | H5: 19.98 | I5: 28.72 | J5: 16.8 | K5: 12.66 | L5: 25.51 | M5: 18.93 | N5: 26.08 | O5: 42.16 | P5: 28.35 | Q5: 20.33 | R5: 23.41 | S5: 38.78 | T5: 17.11 | U5: 7.44 | V5: 14.02 | W5: 9.14 | X5: 44.76 | Y5: 16.33 | Z5: 9.66 | AA5: 30.89 | AB5: 38.46 | AC5: 35.65 | AD5: 42.27
A6: Stop 4 | B6: 8.46 | C6: 27.84 | D6: 10.74 | E6: 16.71 | F6: 0 | G6: 8.88 | H6: 5.13 | I6: 13.13 | J6: 18.1 | K6: 18.04 | L6: 10.36 | M6: 9.41 | N6: 10.32 | O6: 26.66 | P6: 11.71 | Q6: 9.62 | R6: 11.3 | S6: 22.57 | T6: 3.21 | U6: 21.18 | V6: 16.21 | W6: 14.4 | X6: 29.96 | Y6: 10.72 | Z6: 12.25 | AA6: 14.45 | AB6: 21.86 | AC6: 19.09 | AD6: 27.56
A7: Stop 5 | B7: 16.04 | C7: 36.49 | D7: 18.72 | E7: 23.46 | F7: 8.88 | G7: 0 | H7: 11.45 | I7: 14.7 | J7: 17.65 | K7: 26.88 | L7: 13.64 | M7: 17.26 | N7: 12.51 | O7: 26.21 | P7: 7.79 | Q7: 16.92 | R7: 17.31 | S7: 15.65 | T7: 11.47 | U7: 29.12 | V7: 17.08 | W7: 17.85 | X7: 30.35 | Y7: 19.32 | Z7: 15.81 | AA7: 13.34 | AB7: 16.17 | AC7: 13.39 | AD7: 28.26
A8: Stop 6 | B8: 4.67 | C8: 28.17 | D8: 7.45 | E8: 19.98 | F8: 5.13 | G8: 11.45 | H8: 0 | I8: 8.76 | J8: 23.23 | K8: 17.93 | L8: 5.64 | M8: 5.97 | N8: 6.1 | O8: 22.31 | P8: 10.59 | Q8: 5.47 | R8: 6.34 | S8: 21.85 | T8: 2.92 | U8: 23.03 | V8: 21.32 | W8: 19.2 | X8: 25.3 | Y8: 8.75 | Z8: 17.11 | AA8: 11.16 | AB8: 20.33 | AC8: 17.79 | AD8: 22.85
A9: Stop 7 | B9: 10.63 | C9: 35.21 | D9: 12.75 | E9: 28.72 | F9: 13.13 | G9: 14.7 | H9: 8.76 | I9: 0 | J9: 30.46 | K9: 25.03 | L9: 3.27 | M9: 11.72 | N9: 2.81 | O9: 13.59 | P9: 8.53 | Q9: 10.27 | R9: 7.81 | S9: 17.41 | T9: 11.68 | U9: 31.28 | V9: 28.96 | W9: 27.52 | X9: 16.86 | Y9: 15.3 | Z9: 25.37 | AA9: 4.2 | AB9: 14.72 | AC9: 12.94 | AD9: 14.49
A10: Stop 8 | B10: 25.87 | C10: 33.79 | D10: 27.38 | E10: 16.8 | F10: 18.1 | G10: 17.65 | H10: 23.23 | I10: 30.46 | J10: 0 | K10: 27.7 | L10: 28.16 | M10: 26.42 | N10: 27.73 | O10: 43.32 | P10: 25.31 | Q10: 27.12 | R10: 29.28 | S10: 32.15 | T10: 20.92 | U10: 24.24 | V10: 2.85 | W10: 7.77 | X10: 47.15 | Y10: 25.97 | Z10: 8.28 | AA10: 30.37 | AB10: 33.44 | AC10: 30.78 | AD10: 44.87
A11: Stop 9 | B11: 14.44 | C11: 10.26 | D11: 12.38 | E11: 12.66 | F11: 18.04 | G11: 26.88 | H11: 17.93 | I11: 25.03 | J11: 27.7 | K11: 0 | L11: 21.89 | M11: 13.31 | N11: 23.14 | O11: 36.86 | P11: 28.46 | Q11: 14.78 | R11: 17.61 | S11: 39.74 | T11: 16.12 | U11: 8.8 | V11: 24.86 | W11: 20.09 | X11: 38.32 | Y11: 9.73 | Z11: 19.46 | AA11: 28.52 | AB11: 38.25 | AC11: 35.72 | AD11: 35.89
A12: Stop 10 | B12: 7.45 | C12: 32.11 | D12: 9.76 | E12: 25.51 | F12: 10.36 | G12: 13.64 | H12: 5.64 | I12: 3.27 | J12: 28.16 | K12: 21.89 | L12: 0 | M12: 8.61 | N12: 1.63 | O12: 16.69 | P12: 9.11 | Q12: 7.23 | R12: 5.26 | S12: 19.37 | T12: 8.56 | U12: 28.01 | V12: 26.48 | W12: 24.71 | X12: 19.69 | Y12: 12.17 | Z12: 22.58 | AA12: 6.73 | AB12: 17.07 | AC12: 14.96 | AD12: 17.25
A13: Stop 11 | B13: 1.35 | C13: 23.5 | D13: 1.48 | E13: 18.93 | F13: 9.41 | G13: 17.26 | H13: 5.97 | I13: 11.72 | J13: 26.42 | K13: 13.31 | L13: 8.61 | M13: 0 | N13: 9.95 | O13: 24.04 | P13: 16.2 | Q13: 1.53 | R13: 4.63 | S13: 27.3 | T13: 6.21 | U13: 20.03 | V13: 24.09 | W13: 20.9 | X13: 26.11 | Y13: 3.58 | Z13: 19.09 | AA13: 15.31 | AB13: 25.39 | AC13: 23.04 | AD13: 23.63
... A30: Stop 28 | B30: 23.04 | C30: 45.27 | D30: 24.01 | E30: 42.27 | F30: 27.56 | G30: 28.26 | H30: 22.85 | I30: 14.49 | J30: 44.87 | K30: 35.89 | L30: 17.25 | M30: 23.63 | N30: 17.29 | O30: 3.8 | P30: 20.72 | Q30: 22.13 | R30: 19 | S30: 23.28 | T30: 25.74 | U30: 43.54 | V30: 43.44 | W30: 41.95 | X30: 2.49 | Y30: 26.89 | Z30: 39.81 | AA30: 14.93 | AB30: 19.59 | AC30: 19.99 | AD30: 0

Sheet Travel Time Matrix (min)
B1: Depot | C1: Stop 1 | D1: Stop 2 | E1: Stop 3 | F1: Stop 4 | G1: Stop 5 | H1: Stop 6 | I1: Stop 7 | J1: Stop 8 | K1: Stop 9 | L1: Stop 10 | M1: Stop 11 | N1: Stop 12 | O1: Stop 13 | P1: Stop 14 | Q1: Stop 15 | R1: Stop 16 | S1: Stop 17 | T1: Stop 18 | U1: Stop 19 | V1: Stop 20 | W1: Stop 21 | X1: Stop 22 | Y1: Stop 23 | Z1: Stop 24 | AA1: Stop 25 | AB1: Stop 26 | AC1: Stop 27 | AD1: Stop 28
A2: Depot | B2: 0 | C2: 37 | D2: 4.2 | E2: 29 | F2: 12.7 | G2: 24.1 | H2: 7 | I2: 15.9 | J2: 38.8 | K2: 21.7 | L2: 11.2 | M2: 2 | N2: 13.1 | O2: 34.9 | P2: 22.3 | Q2: 1.9 | R2: 6.2 | S2: 39 | T2: 7.9 | U2: 31.3 | V2: 35.4 | W2: 31 | X2: 38.3 | Y2: 7.1 | Z2: 28.2 | AA2: 21.1 | AB2: 36.1 | AC2: 32.6 | AD2: 34.6
A3: Stop 1 | B3: 37 | C3: 0 | D3: 33.7 | E3: 25.5 | F3: 41.8 | G3: 54.7 | H3: 42.3 | I3: 52.8 | J3: 50.7 | K3: 15.4 | L3: 48.2 | M3: 35.2 | N3: 50.1 | O3: 69.9 | P3: 58 | Q3: 37.4 | R3: 41.5 | S3: 74.9 | T3: 39.3 | U3: 14.4 | V3: 46.5 | W3: 39.1 | X3: 71.4 | Y3: 29.9 | Z3: 39.3 | AA3: 58.2 | AB3: 72.7 | AC3: 68.9 | AD3: 67.9
A4: Stop 2 | B4: 4.2 | C4: 33.7 | D4: 0 | E4: 28.5 | F4: 16.1 | G4: 28.1 | H4: 11.2 | I4: 19.1 | J4: 41.1 | K4: 18.6 | L4: 14.6 | M4: 2.2 | N4: 16.8 | O4: 37 | P4: 26.4 | Q4: 3.8 | R4: 7.9 | S4: 43 | T4: 11.4 | U4: 29.3 | V4: 37.5 | W4: 32.4 | X4: 39.7 | Y4: 4.3 | Z4: 29.8 | AA4: 24.7 | AB4: 40 | AC4: 36.6 | AD4: 36
A5: Stop 3 | B5: 29 | C5: 25.5 | D5: 28.5 | E5: 0 | F5: 25.1 | G5: 35.2 | H5: 30 | I5: 43.1 | J5: 25.2 | K5: 19 | L5: 38.3 | M5: 28.4 | N5: 39.1 | O5: 63.2 | P5: 42.5 | Q5: 30.5 | R5: 35.1 | S5: 58.2 | T5: 25.7 | U5: 11.2 | V5: 21 | W5: 13.7 | X5: 67.1 | Y5: 24.5 | Z5: 14.5 | AA5: 46.3 | AB5: 57.7 | AC5: 53.5 | AD5: 63.4
A6: Stop 4 | B6: 12.7 | C6: 41.8 | D6: 16.1 | E6: 25.1 | F6: 0 | G6: 13.3 | H6: 7.7 | I6: 19.7 | J6: 27.2 | K6: 27.1 | L6: 15.5 | M6: 14.1 | N6: 15.5 | O6: 40 | P6: 17.6 | Q6: 14.4 | R6: 17 | S6: 33.9 | T6: 4.8 | U6: 31.8 | V6: 24.3 | W6: 21.6 | X6: 44.9 | Y6: 16.1 | Z6: 18.4 | AA6: 21.7 | AB6: 32.8 | AC6: 28.6 | AD6: 41.3
A7: Stop 5 | B7: 24.1 | C7: 54.7 | D7: 28.1 | E7: 35.2 | F7: 13.3 | G7: 0 | H7: 17.2 | I7: 22.1 | J7: 26.5 | K7: 40.3 | L7: 20.5 | M7: 25.9 | N7: 18.8 | O7: 39.3 | P7: 11.7 | Q7: 25.4 | R7: 26 | S7: 23.5 | T7: 17.2 | U7: 43.7 | V7: 25.6 | W7: 26.8 | X7: 45.5 | Y7: 29 | Z7: 23.7 | AA7: 20 | AB7: 24.3 | AC7: 20.1 | AD7: 42.4
A8: Stop 6 | B8: 7 | C8: 42.3 | D8: 11.2 | E8: 30 | F8: 7.7 | G8: 17.2 | H8: 0 | I8: 13.1 | J8: 34.8 | K8: 26.9 | L8: 8.5 | M8: 9 | N8: 9.2 | O8: 33.5 | P8: 15.9 | Q8: 8.2 | R8: 9.5 | S8: 32.8 | T8: 4.4 | U8: 34.5 | V8: 32 | W8: 28.8 | X8: 38 | Y8: 13.1 | Z8: 25.7 | AA8: 16.7 | AB8: 30.5 | AC8: 26.7 | AD8: 34.3
A9: Stop 7 | B9: 15.9 | C9: 52.8 | D9: 19.1 | E9: 43.1 | F9: 19.7 | G9: 22.1 | H9: 13.1 | I9: 0 | J9: 45.7 | K9: 37.5 | L9: 4.9 | M9: 17.6 | N9: 4.2 | O9: 20.4 | P9: 12.8 | Q9: 15.4 | R9: 11.7 | S9: 26.1 | T9: 17.5 | U9: 46.9 | V9: 43.4 | W9: 41.3 | X9: 25.3 | Y9: 22.9 | Z9: 38.1 | AA9: 6.3 | AB9: 22.1 | AC9: 19.4 | AD9: 21.7
A10: Stop 8 | B10: 38.8 | C10: 50.7 | D10: 41.1 | E10: 25.2 | F10: 27.2 | G10: 26.5 | H10: 34.8 | I10: 45.7 | J10: 0 | K10: 41.5 | L10: 42.2 | M10: 39.6 | N10: 41.6 | O10: 65 | P10: 38 | Q10: 40.7 | R10: 43.9 | S10: 48.2 | T10: 31.4 | U10: 36.4 | V10: 4.3 | W10: 11.7 | X10: 70.7 | Y10: 39 | Z10: 12.4 | AA10: 45.6 | AB10: 50.2 | AC10: 46.2 | AD10: 67.3
A11: Stop 9 | B11: 21.7 | C11: 15.4 | D11: 18.6 | E11: 19 | F11: 27.1 | G11: 40.3 | H11: 26.9 | I11: 37.5 | J11: 41.5 | K11: 0 | L11: 32.8 | M11: 20 | N11: 34.7 | O11: 55.3 | P11: 42.7 | Q11: 22.2 | R11: 26.4 | S11: 59.6 | T11: 24.2 | U11: 13.2 | V11: 37.3 | W11: 30.1 | X11: 57.5 | Y11: 14.6 | Z11: 29.2 | AA11: 42.8 | AB11: 57.4 | AC11: 53.6 | AD11: 53.8
A12: Stop 10 | B12: 11.2 | C12: 48.2 | D12: 14.6 | E12: 38.3 | F12: 15.5 | G12: 20.5 | H12: 8.5 | I12: 4.9 | J12: 42.2 | K12: 32.8 | L12: 0 | M12: 12.9 | N12: 2.4 | O12: 25 | P12: 13.7 | Q12: 10.8 | R12: 7.9 | S12: 29.1 | T12: 12.8 | U12: 42 | V12: 39.7 | W12: 37.1 | X12: 29.5 | Y12: 18.3 | Z12: 33.9 | AA12: 10.1 | AB12: 25.6 | AC12: 22.4 | AD12: 25.9
A13: Stop 11 | B13: 2 | C13: 35.2 | D13: 2.2 | E13: 28.4 | F13: 14.1 | G13: 25.9 | H13: 9 | I13: 17.6 | J13: 39.6 | K13: 20 | L13: 12.9 | M13: 0 | N13: 14.9 | O13: 36.1 | P13: 24.3 | Q13: 2.3 | R13: 6.9 | S13: 41 | T13: 9.3 | U13: 30 | V13: 36.1 | W13: 31.3 | X13: 39.2 | Y13: 5.4 | Z13: 28.6 | AA13: 23 | AB13: 38.1 | AC13: 34.6 | AD13: 35.4
... A30: Stop 28 | B30: 34.6 | C30: 67.9 | D30: 36 | E30: 63.4 | F30: 41.3 | G30: 42.4 | H30: 34.3 | I30: 21.7 | J30: 67.3 | K30: 53.8 | L30: 25.9 | M30: 35.4 | N30: 25.9 | O30: 5.7 | P30: 31.1 | Q30: 33.2 | R30: 28.5 | S30: 34.9 | T30: 38.6 | U30: 65.3 | V30: 65.2 | W30: 62.9 | X30: 3.7 | Y30: 40.3 | Z30: 59.7 | AA30: 22.4 | AB30: 29.4 | AC30: 30 | AD30: 0

Sheet Cost Parameters
A1: Parameter | B1: Value
A2: Fuel_Cost_per_Liter | B2: 1.98
A3: Avg_Fuel_Consumption_L_per_mile | B3: 0.18
A4: Driver_Hourly_Wage | B4: 22
A5: Late_Delivery_Penalty_per_Hour | B5: 61
A6: Early_Delivery_Penalty | B6: 0
A7: Overtime_Hourly_Rate | B7: 33
A8: Vehicle_Idle_Cost_per_Hour | B8: 6
A9: Regular_Hours_Before_Overtime | B9: 8

Sheet Solver Setup
A1: Vehicle Routing Solver Setup
A2: Minimize total cost while satisfying stop visits, routing flow, vehicle capacity, stop windows, and depot/vehicle hours.
A4: Objective Cell | B4: Solver Setup!$E$5 | D4: Metric | E4: Value
A5: Optimize | B5: Min | D5: Total Cost | E5: =SUM(U15:U19)+SUM(P25:P52) -> 0
A6: Changing Cells | B6: Solver Arcs!$F$2:$F$4061, Solver Setup!$L$15:$M$19, Solver Setup!$G$25:$G$52, Solver Setup!$K$25:$M$52 | D6: Total Miles | E6: =SUM(S15:S19) -> 0
A7: Binary Cells | B7: Solver Arcs!$F$2:$F$4061, Solver Setup!$M$25:$M$52 | D7: Vehicles Used | E7: =SUM(C15:C19) -> 0
A8: Recommended Engine | B8: MILP-capable solver (OpenSolver/CBC or Analytic Solver) | D8: Stop Visit Violations | E8: =COUNTIF(I25:I52,"<>0") -> 28
A9: Big-M (minutes) | B9: 1440 | D9: Soft Window Stops | E9: =COUNTIF(K25:K52,">0")+COUNTIF(L25:L52,">0") -> 0
A10: Model Note | B10: Vehicle cost includes fixed cost, mileage/fuel, driver labor on active hours, overtime after 8.0 active hours, and idle waiting cost within the active window. | D10: Flow Violations | E10: =COUNTIF(B57:AC61,"<>0") -> 0
D11: Vehicle/Capacity Violations | E11: =COUNTIF(E15:E19,"<0")+COUNTIF(F15:F19,"<>0")+COUNTIF(I15:I19,"<0")+COUNTIF(N15:R19,"<0") -> 0
D12: Time Arc Violations | E12: =COUNTIF('Solver Arcs'!$O$2:$O$4061,"<0") -> 0
D13: Overall Feasible | E13: =IF(E8+E10+E11+E12=0,"OK","Not yet") -> Not yet
A14: Vehicle_ID | B14: Type | C14: Start_Arcs | D14: Return_Arcs | E14: Start_≤1_Slack | F14: Start-Return_Check | G14: Capacity_kg | H14: Assigned_kg | I14: Capacity_Slack | J14: Start_Limit | K14: End_Limit | L14: Depart_Time | M14: Return_Time | N14: Depart_Lower_Slack_min | O14: Depart_Upper_Slack_min | P14: Return_Lower_Slack_min | Q14: Return_Upper_Slack_min | R14: Active_Window_Min | S14: Distance_mi | T14: Active_Hours | U14: Vehicle_Cost | V14: Drive_Min | W14: Service_Min | X14: Idle_Min | Y14: Idle_Hours | Z14: Regular_Hours | AA14: Overtime_Hours | AB14: Labor_Cost | AC14: Idle_Cost
A15: 1 | B15: {=INDEX('Vehicle Fleet'!$B$2:$B$6,$A15)} -> Small Van | C15: =SUMIFS('Solver Arcs'!$F$2:$F$4061,'Solver Arcs'!$A$2:$A$4061,$A15,'Solver Arcs'!$B$2:$B$4061,0) -> 0 | D15: =SUMIFS('Solver Arcs'!$F$2:$F$4061,'Solver Arcs'!$A$2:$A$4061,$A15,'Solver Arcs'!$C$2:$C$4061,0) -> 0 | E15: =1-C15 -> 1 | F15: =C15-D15 -> 0 | G15: {=INDEX('Vehicle Fleet'!$C$2:$C$6,$A15)} -> 600 | H15: =SUMIFS('Solver Arcs'!$N$2:$N$4061,'Solver Arcs'!$A$2:$A$4061,$A15) -> 0 | I15: =G15-H15 -> 600 | J15: {=MAX(INDEX('Vehicle Fleet'!$F$2:$F$6,$A15)+0,Depot!$C$2+0)} -> 0.25 | K15: {=MIN(INDEX('Vehicle Fleet'!$G$2:$G$6,$A15)+0,Depot!$D$2+0)} -> 0.83333333 | L15: 0 | M15: 0 | N15: =(L15-J15*C15)*1440 -> 0 | O15: =(K15*C15-L15)*1440 -> 0 | P15: =(M15-J15*C15)*1440 -> 0 | Q15: =(K15*C15-M15)*1440 -> 0 | R15: =(M15-L15)*1440 -> 0 | S15: =SUMIFS('Solver Arcs'!$L$2:$L$4061,'Solver Arcs'!$A$2:$A$4061,$A15) -> 0 | T15: =(M15-L15)*24 -> 0 | U15: {=SUMIFS('Solver Arcs'!$K$2:$K$4061,'Solver Arcs'!$A$2:$A$4061,$A15)+C15*INDEX('Vehicle Fleet'!$E$2:$E$6,$A15)+AB15+AC15} -> 0 | V15: =SUMIFS('Solver Arcs'!$M$2:$M$4061,'Solver Arcs'!$A$2:$A$4061,$A15) -> 0 | W15: =SUMIFS($F$25:$F$52,$J$25:$J$52,$A15) -> 0 | X15: =MAX(R15-V15-W15,0) -> 0 | Y15: =X15/60 -> 0 | Z15: =MIN(T15,'Cost Parameters'!$B$9) -> 0 | AA15: =MAX(T15-'Cost Parameters'!$B$9,0) -> 0 | AB15: =Z15*'Cost Parameters'!$B$4+AA15*'Cost Parameters'!$B$7 -> 0 | AC15: =Y15*'Cost Parameters'!$B$8 -> 0
A16: 2 | B16: {=INDEX('Vehicle Fleet'!$B$2:$B$6,$A16)} -> Small Van | C16: =SUMIFS('Solver Arcs'!$F$2:$F$4061,'Solver Arcs'!$A$2:$A$4061,$A16,'Solver Arcs'!$B$2:$B$4061,0) -> 0 | D16: =SUMIFS('Solver Arcs'!$F$2:$F$4061,'Solver Arcs'!$A$2:$A$4061,$A16,'Solver Arcs'!$C$2:$C$4061,0) -> 0 | E16: =1-C16 -> 1 | F16: =C16-D16 -> 0 | G16: {=INDEX('Vehicle Fleet'!$C$2:$C$6,$A16)} -> 600 | H16: =SUMIFS('Solver Arcs'!$N$2:$N$4061,'Solver Arcs'!$A$2:$A$4061,$A16) -> 0 | I16: =G16-H16 -> 600 | J16: {=MAX(INDEX('Vehicle Fleet'!$F$2:$F$6,$A16)+0,Depot!$C$2+0)} -> 0.25 | K16: {=MIN(INDEX('Vehicle Fleet'!$G$2:$G$6,$A16)+0,Depot!$D$2+0)} -> 0.83333333 | L16: 0 | M16: 0 | N16: =(L16-J16*C16)*1440 -> 0 | O16: =(K16*C16-L16)*1440 -> 0 | P16: =(M16-J16*C16)*1440 -> 0 | Q16: =(K16*C16-M16)*1440 -> 0 | R16: =(M16-L16)*1440 -> 0 | S16: =SUMIFS('Solver Arcs'!$L$2:$L$4061,'Solver Arcs'!$A$2:$A$4061,$A16) -> 0 | T16: =(M16-L16)*24 -> 0 | U16: {=SUMIFS('Solver Arcs'!$K$2:$K$4061,'Solver Arcs'!$A$2:$A$4061,$A16)+C16*INDEX('Vehicle Fleet'!$E$2:$E$6,$A16)+AB16+AC16} -> 0 | V16: =SUMIFS('Solver Arcs'!$M$2:$M$4061,'Solver Arcs'!$A$2:$A$4061,$A16) -> 0 | W16: =SUMIFS($F$25:$F$52,$J$25:$J$52,$A16) -> 0 | X16: =MAX(R16-V16-W16,0) -> 0 | Y16: =X16/60 -> 0 | Z16: =MIN(T16,'Cost Parameters'!$B$9) -> 0 | AA16: =MAX(T16-'Cost Parameters'!$B$9,0) -> 0 | AB16: =Z16*'Cost Parameters'!$B$4+AA16*'Cost Parameters'!$B$7 -> 0 | AC16: =Y16*'Cost Parameters'!$B$8 -> 0
A17: 3 | B17: {=INDEX('Vehicle Fleet'!$B$2:$B$6,$A17)} -> Medium Truck | C17: =SUMIFS('Solver Arcs'!$F$2:$F$4061,'Solver Arcs'!$A$2:$A$4061,$A17,'Solver Arcs'!$B$2:$B$4061,0) -> 0 | D17: =SUMIFS('Solver Arcs'!$F$2:$F$4061,'Solver Arcs'!$A$2:$A$4061,$A17,'Solver Arcs'!$C$2:$C$4061,0) -> 0 | E17: =1-C17 -> 1 | F17: =C17-D17 -> 0 | G17: {=INDEX('Vehicle Fleet'!$C$2:$C$6,$A17)} -> 1400 | H17: =SUMIFS('Solver Arcs'!$N$2:$N$4061,'Solver Arcs'!$A$2:$A$4061,$A17) -> 0 | I17: =G17-H17 -> 1400 | J17: {=MAX(INDEX('Vehicle Fleet'!$F$2:$F$6,$A17)+0,Depot!$C$2+0)} -> 0.25 | K17: {=MIN(INDEX('Vehicle Fleet'!$G$2:$G$6,$A17)+0,Depot!$D$2+0)} -> 0.83333333 | L17: 0 | M17: 0 | N17: =(L17-J17*C17)*1440 -> 0 | O17: =(K17*C17-L17)*1440 -> 0 | P17: =(M17-J17*C17)*1440 -> 0 | Q17: =(K17*C17-M17)*1440 -> 0 | R17: =(M17-L17)*1440 -> 0 | S17: =SUMIFS('Solver Arcs'!$L$2:$L$4061,'Solver Arcs'!$A$2:$A$4061,$A17) -> 0 | T17: =(M17-L17)*24 -> 0 | U17: {=SUMIFS('Solver Arcs'!$K$2:$K$4061,'Solver Arcs'!$A$2:$A$4061,$A17)+C17*INDEX('Vehicle Fleet'!$E$2:$E$6,$A17)+AB17+AC17} -> 0 | V17: =SUMIFS('Solver Arcs'!$M$2:$M$4061,'Solver Arcs'!$A$2:$A$4061,$A17) -> 0 | W17: =SUMIFS($F$25:$F$52,$J$25:$J$52,$A17) -> 0 | X17: =MAX(R17-V17-W17,0) -> 0 | Y17: =X17/60 -> 0 | Z17: =MIN(T17,'Cost Parameters'!$B$9) -> 0 | AA17: =MAX(T17-'Cost Parameters'!$B$9,0) -> 0 | AB17: =Z17*'Cost Parameters'!$B$4+AA17*'Cost Parameters'!$B$7 -> 0 | AC17: =Y17*'Cost Parameters'!$B$8 -> 0
A18: 4 | B18: {=INDEX('Vehicle Fleet'!$B$2:$B$6,$A18)} -> Medium Truck | C18: =SUMIFS('Solver Arcs'!$F$2:$F$4061,'Solver Arcs'!$A$2:$A$4061,$A18,'Solver Arcs'!$B$2:$B$4061,0) -> 0 | D18: =SUMIFS('Solver Arcs'!$F$2:$F$4061,'Solver Arcs'!$A$2:$A$4061,$A18,'Solver Arcs'!$C$2:$C$4061,0) -> 0 | E18: =1-C18 -> 1 | F18: =C18-D18 -> 0 | G18: {=INDEX('Vehicle Fleet'!$C$2:$C$6,$A18)} -> 1400 | H18: =SUMIFS('Solver Arcs'!$N$2:$N$4061,'Solver Arcs'!$A$2:$A$4061,$A18) -> 0 | I18: =G18-H18 -> 1400 | J18: {=MAX(INDEX('Vehicle Fleet'!$F$2:$F$6,$A18)+0,Depot!$C$2+0)} -> 0.25 | K18: {=MIN(INDEX('Vehicle Fleet'!$G$2:$G$6,$A18)+0,Depot!$D$2+0)} -> 0.83333333 | L18: 0 | M18: 0 | N18: =(L18-J18*C18)*1440 -> 0 | O18: =(K18*C18-L18)*1440 -> 0 | P18: =(M18-J18*C18)*1440 -> 0 | Q18: =(K18*C18-M18)*1440 -> 0 | R18: =(M18-L18)*1440 -> 0 | S18: =SUMIFS('Solver Arcs'!$L$2:$L$4061,'Solver Arcs'!$A$2:$A$4061,$A18) -> 0 | T18: =(M18-L18)*24 -> 0 | U18: {=SUMIFS('Solver Arcs'!$K$2:$K$4061,'Solver Arcs'!$A$2:$A$4061,$A18)+C18*INDEX('Vehicle Fleet'!$E$2:$E$6,$A18)+AB18+AC18} -> 0 | V18: =SUMIFS('Solver Arcs'!$M$2:$M$4061,'Solver Arcs'!$A$2:$A$4061,$A18) -> 0 | W18: =SUMIFS($F$25:$F$52,$J$25:$J$52,$A18) -> 0 | X18: =MAX(R18-V18-W18,0) -> 0 | Y18: =X18/60 -> 0 | Z18: =MIN(T18,'Cost Parameters'!$B$9) -> 0 | AA18: =MAX(T18-'Cost Parameters'!$B$9,0) -> 0 | AB18: =Z18*'Cost Parameters'!$B$4+AA18*'Cost Parameters'!$B$7 -> 0 | AC18: =Y18*'Cost Parameters'!$B$8 -> 0
A19: 5 | B19: {=INDEX('Vehicle Fleet'!$B$2:$B$6,$A19)} -> Large Truck | C19: =SUMIFS('Solver Arcs'!$F$2:$F$4061,'Solver Arcs'!$A$2:$A$4061,$A19,'Solver Arcs'!$B$2:$B$4061,0) -> 0 | D19: =SUMIFS('Solver Arcs'!$F$2:$F$4061,'Solver Arcs'!$A$2:$A$4061,$A19,'Solver Arcs'!$C$2:$C$4061,0) -> 0 | E19: =1-C19 -> 1 | F19: =C19-D19 -> 0 | G19: {=INDEX('Vehicle Fleet'!$C$2:$C$6,$A19)} -> 2800 | H19: =SUMIFS('Solver Arcs'!$N$2:$N$4061,'Solver Arcs'!$A$2:$A$4061,$A19) -> 0 | I19: =G19-H19 -> 2800 | J19: {=MAX(INDEX('Vehicle Fleet'!$F$2:$F$6,$A19)+0,Depot!$C$2+0)} -> 0.25 | K19: {=MIN(INDEX('Vehicle Fleet'!$G$2:$G$6,$A19)+0,Depot!$D$2+0)} -> 0.83333333 | L19: 0 | M19: 0 | N19: =(L19-J19*C19)*1440 -> 0 | O19: =(K19*C19-L19)*1440 -> 0 | P19: =(M19-J19*C19)*1440 -> 0 | Q19: =(K19*C19-M19)*1440 -> 0 | R19: =(M19-L19)*1440 -> 0 | S19: =SUMIFS('Solver Arcs'!$L$2:$L$4061,'Solver Arcs'!$A$2:$A$4061,$A19) -> 0 | T19: =(M19-L19)*24 -> 0 | U19: {=SUMIFS('Solver Arcs'!$K$2:$K$4061,'Solver Arcs'!$A$2:$A$4061,$A19)+C19*INDEX('Vehicle Fleet'!$E$2:$E$6,$A19)+AB19+AC19} -> 0 | V19: =SUMIFS('Solver Arcs'!$M$2:$M$4061,'Solver Arcs'!$A$2:$A$4061,$A19) -> 0 | W19: =SUMIFS($F$25:$F$52,$J$25:$J$52,$A19) -> 0 | X19: =MAX(R19-V19-W19,0) -> 0 | Y19: =X19/60 -> 0 | Z19: =MIN(T19,'Cost Parameters'!$B$9) -> 0 | AA19: =MAX(T19-'Cost Parameters'!$B$9,0) -> 0 | AB19: =Z19*'Cost Parameters'!$B$4+AA19*'Cost Parameters'!$B$7 -> 0 | AC19: =Y19*'Cost Parameters'!$B$8 -> 0
A24: Stop_ID | B24: Customer_Name | C24: Demand_kg | D24: Earliest | E24: Latest | F24: Service_min | G24: Service_Start | H24: Visit_Total | I24: Visit_Check | J24: Assigned_Vehicle | K24: Early_Min | L24: Late_Min | M24: Early_Flag | N24: Earliest_Coverage_Min | O24: Latest_Coverage_Min | P24: Window_Penalty_Cost | Q24: Early_Flag_Link_Min | R24: Early_Flag_Floor_Min
A25: 1 | B25: {=INDEX('Delivery Stops'!$B$2:$B$29,$A25)} -> Pet Hospital | C25: {=INDEX('Delivery Stops'!$D$2:$D$29,$A25)} -> 204 | D25: {=INDEX('Delivery Stops'!$E$2:$E$29,$A25)} -> 08:30 | E25: {=INDEX('Delivery Stops'!$F$2:$F$29,$A25)} -> 18:15 | F25: {=INDEX('Delivery Stops'!$G$2:$G$29,$A25)} -> 29 | G25: 0.35416667 | H25: =SUMIFS('Solver Arcs'!$F$2:$F$4061,'Solver Arcs'!$C$2:$C$4061,$A25) -> 0 | I25: =H25-1 -> -1 | J25: {=SUMPRODUCT(('Solver Arcs'!$A$2:$A$4061)*(('Solver Arcs'!$C$2:$C$4061=$A25)*('Solver Arcs'!$F$2:$F$4061)))} -> 0 | K25: 0 | L25: 0 | M25: 0 | N25: =(G25+K25/1440-D25)*1440 -> 4.7961635e-13 | O25: =(E25+L25/1440-G25)*1440 -> 585 | P25: =M25*'Cost Parameters'!$B$6+L25/60*'Cost Parameters'!$B$5 -> 0 | Q25: ='Solver Setup'!$B$9*M25-K25 -> 0 | R25: =K25-0.001*M25 -> 0
A26: 2 | B26: {=INDEX('Delivery Stops'!$B$2:$B$29,$A26)} -> Community Pharmacy | C26: {=INDEX('Delivery Stops'!$D$2:$D$29,$A26)} -> 240 | D26: {=INDEX('Delivery Stops'!$E$2:$E$29,$A26)} -> 12:30 | E26: {=INDEX('Delivery Stops'!$F$2:$F$29,$A26)} -> 18:30 | F26: {=INDEX('Delivery Stops'!$G$2:$G$29,$A26)} -> 11 | G26: 0.52083333 | H26: =SUMIFS('Solver Arcs'!$F$2:$F$4061,'Solver Arcs'!$C$2:$C$4061,$A26) -> 0 | I26: =H26-1 -> -1 | J26: {=SUMPRODUCT(('Solver Arcs'!$A$2:$A$4061)*(('Solver Arcs'!$C$2:$C$4061=$A26)*('Solver Arcs'!$F$2:$F$4061)))} -> 0 | K26: 0 | L26: 0 | M26: 0 | N26: =(G26+K26/1440-D26)*1440 -> -4.7961635e-13 | O26: =(E26+L26/1440-G26)*1440 -> 360 | P26: =M26*'Cost Parameters'!$B$6+L26/60*'Cost Parameters'!$B$5 -> 0 | Q26: ='Solver Setup'!$B$9*M26-K26 -> 0 | R26: =K26-0.001*M26 -> 0
A27: 3 | B27: {=INDEX('Delivery Stops'!$B$2:$B$29,$A27)} -> Redstone Medical Center | C27: {=INDEX('Delivery Stops'!$D$2:$D$29,$A27)} -> 183 | D27: {=INDEX('Delivery Stops'!$E$2:$E$29,$A27)} -> 12:45 | E27: {=INDEX('Delivery Stops'!$F$2:$F$29,$A27)} -> 17:15 | F27: {=INDEX('Delivery Stops'!$G$2:$G$29,$A27)} -> 17 | G27: 0.53125 | H27: =SUMIFS('Solver Arcs'!$F$2:$F$4061,'Solver Arcs'!$C$2:$C$4061,$A27) -> 0 | I27: =H27-1 -> -1 | J27: {=SUMPRODUCT(('Solver Arcs'!$A$2:$A$4061)*(('Solver Arcs'!$C$2:$C$4061=$A27)*('Solver Arcs'!$F$2:$F$4061)))} -> 0 | K27: 0 | L27: 0 | M27: 0 | N27: =(G27+K27/1440-D27)*1440 -> 0 | O27: =(E27+L27/1440-G27)*1440 -> 270 | P27: =M27*'Cost Parameters'!$B$6+L27/60*'Cost Parameters'!$B$5 -> 0 | Q27: ='Solver Setup'!$B$9*M27-K27 -> 0 | R27: =K27-0.001*M27 -> 0
A28: 4 | B28: {=INDEX('Delivery Stops'!$B$2:$B$29,$A28)} -> Furniture Warehouse | C28: {=INDEX('Delivery Stops'!$D$2:$D$29,$A28)} -> 186 | D28: {=INDEX('Delivery Stops'!$E$2:$E$29,$A28)} -> 08:15 | E28: {=INDEX('Delivery Stops'!$F$2:$F$29,$A28)} -> 14:15 | F28: {=INDEX('Delivery Stops'!$G$2:$G$29,$A28)} -> 24 | G28: 0.34375 | H28: =SUMIFS('Solver Arcs'!$F$2:$F$4061,'Solver Arcs'!$C$2:$C$4061,$A28) -> 0 | I28: =H28-1 -> -1 | J28: {=SUMPRODUCT(('Solver Arcs'!$A$2:$A$4061)*(('Solver Arcs'!$C$2:$C$4061=$A28)*('Solver Arcs'!$F$2:$F$4061)))} -> 0 | K28: 0 | L28: 0 | M28: 0 | N28: =(G28+K28/1440-D28)*1440 -> 0 | O28: =(E28+L28/1440-G28)*1440 -> 360 | P28: =M28*'Cost Parameters'!$B$6+L28/60*'Cost Parameters'!$B$5 -> 0 | Q28: ='Solver Setup'!$B$9*M28-K28 -> 0 | R28: =K28-0.001*M28 -> 0
A29: 5 | B29: {=INDEX('Delivery Stops'!$B$2:$B$29,$A29)} -> Construction Supply | C29: {=INDEX('Delivery Stops'!$D$2:$D$29,$A29)} -> 201 | D29: {=INDEX('Delivery Stops'!$E$2:$E$29,$A29)} -> 11:45 | E29: {=INDEX('Delivery Stops'!$F$2:$F$29,$A29)} -> 14:45 | F29: {=INDEX('Delivery Stops'!$G$2:$G$29,$A29)} -> 30 | G29: 0.48958333 | H29: =SUMIFS('Solver Arcs'!$F$2:$F$4061,'Solver Arcs'!$C$2:$C$4061,$A29) -> 0 | I29: =H29-1 -> -1 | J29: {=SUMPRODUCT(('Solver Arcs'!$A$2:$A$4061)*(('Solver Arcs'!$C$2:$C$4061=$A29)*('Solver Arcs'!$F$2:$F$4061)))} -> 0 | K29: 0 | L29: 0 | M29: 0 | N29: =(G29+K29/1440-D29)*1440 -> -4.7961635e-13 | O29: =(E29+L29/1440-G29)*1440 -> 180 | P29: =M29*'Cost Parameters'!$B$6+L29/60*'Cost Parameters'!$B$5 -> 0 | Q29: ='Solver Setup'!$B$9*M29-K29 -> 0 | R29: =K29-0.001*M29 -> 0
A30: 6 | B30: {=INDEX('Delivery Stops'!$B$2:$B$29,$A30)} -> Farm Supply | C30: {=INDEX('Delivery Stops'!$D$2:$D$29,$A30)} -> 162 | D30: {=INDEX('Delivery Stops'!$E$2:$E$29,$A30)} -> 13:30 | E30: {=INDEX('Delivery Stops'!$F$2:$F$29,$A30)} -> 18:45 | F30: {=INDEX('Delivery Stops'!$G$2:$G$29,$A30)} -> 21 | G30: 0.5625 | H30: =SUMIFS('Solver Arcs'!$F$2:$F$4061,'Solver Arcs'!$C$2:$C$4061,$A30) -> 0 | I30: =H30-1 -> -1 | J30: {=SUMPRODUCT(('Solver Arcs'!$A$2:$A$4061)*(('Solver Arcs'!$C$2:$C$4061=$A30)*('Solver Arcs'!$F$2:$F$4061)))} -> 0 | K30: 0 | L30: 0 | M30: 0 | N30: =(G30+K30/1440-D30)*1440 -> 0 | O30: =(E30+L30/1440-G30)*1440 -> 315 | P30: =M30*'Cost Parameters'!$B$6+L30/60*'Cost Parameters'!$B$5 -> 0 | Q30: ='Solver Setup'!$B$9*M30-K30 -> 0 | R30: =K30-0.001*M30 -> 0
A31: 7 | B31: {=INDEX('Delivery Stops'!$B$2:$B$29,$A31)} -> Fish Market | C31: {=INDEX('Delivery Stops'!$D$2:$D$29,$A31)} -> 133 | D31: {=INDEX('Delivery Stops'!$E$2:$E$29,$A31)} -> 11:15 | E31: {=INDEX('Delivery Stops'!$F$2:$F$29,$A31)} -> 17:45 | F31: {=INDEX('Delivery Stops'!$G$2:$G$29,$A31)} -> 19 | G31: 0.46875 | H31: =SUMIFS('Solver Arcs'!$F$2:$F$4061,'Solver Arcs'!$C$2:$C$4061,$A31) -> 0 | I31: =H31-1 -> -1 | J31: {=SUMPRODUCT(('Solver Arcs'!$A$2:$A$4061)*(('Solver Arcs'!$C$2:$C$4061=$A31)*('Solver Arcs'!$F$2:$F$4061)))} -> 0 | K31: 0 | L31: 0 | M31: 0 | N31: =(G31+K31/1440-D31)*1440 -> 0 | O31: =(E31+L31/1440-G31)*1440 -> 390 | P31: =M31*'Cost Parameters'!$B$6+L31/60*'Cost Parameters'!$B$5 -> 0 | Q31: ='Solver Setup'!$B$9*M31-K31 -> 0 | R31: =K31-0.001*M31 -> 0
A32: 8 | B32: {=INDEX('Delivery Stops'!$B$2:$B$29,$A32)} -> Swimming Pool Supply | C32: {=INDEX('Delivery Stops'!$D$2:$D$29,$A32)} -> 285 | D32: {=INDEX('Delivery Stops'!$E$2:$E$29,$A32)} -> 14:45 | E32: {=INDEX('Delivery Stops'!$F$2:$F$29,$A32)} -> 18:45 | F32: {=INDEX('Delivery Stops'!$G$2:$G$29,$A32)} -> 26 | G32: 0.61458333 | H32: =SUMIFS('Solver Arcs'!$F$2:$F$4061,'Solver Arcs'!$C$2:$C$4061,$A32) -> 0 | I32: =H32-1 -> -1 | J32: {=SUMPRODUCT(('Solver Arcs'!$A$2:$A$4061)*(('Solver Arcs'!$C$2:$C$4061=$A32)*('Solver Arcs'!$F$2:$F$4061)))} -> 0 | K32: 0 | L32: 0 | M32: 0 | N32: =(G32+K32/1440-D32)*1440 -> -4.7961635e-13 | O32: =(E32+L32/1440-G32)*1440 -> 240 | P32: =M32*'Cost Parameters'!$B$6+L32/60*'Cost Parameters'!$B$5 -> 0 | Q32: ='Solver Setup'!$B$9*M32-K32 -> 0 | R32: =K32-0.001*M32 -> 0
A33: 9 | B33: {=INDEX('Delivery Stops'!$B$2:$B$29,$A33)} -> Dry Cleaners | C33: {=INDEX('Delivery Stops'!$D$2:$D$29,$A33)} -> 24 | D33: {=INDEX('Delivery Stops'!$E$2:$E$29,$A33)} -> 09:00 | E33: {=INDEX('Delivery Stops'!$F$2:$F$29,$A33)} -> 11:30 | F33: {=INDEX('Delivery Stops'!$G$2:$G$29,$A33)} -> 28 | G33: 0.375 | H33: =SUMIFS('Solver Arcs'!$F$2:$F$4061,'Solver Arcs'!$C$2:$C$4061,$A33) -> 0 | I33: =H33-1 -> -1 | J33: {=SUMPRODUCT(('Solver Arcs'!$A$2:$A$4061)*(('Solver Arcs'!$C$2:$C$4061=$A33)*('Solver Arcs'!$F$2:$F$4061)))} -> 0 | K33: 0 | L33: 0 | M33: 0 | N33: =(G33+K33/1440-D33)*1440 -> 0 | O33: =(E33+L33/1440-G33)*1440 -> 150 | P33: =M33*'Cost Parameters'!$B$6+L33/60*'Cost Parameters'!$B$5 -> 0 | Q33: ='Solver Setup'!$B$9*M33-K33 -> 0 | R33: =K33-0.001*M33 -> 0
A34: 10 | B34: {=INDEX('Delivery Stops'!$B$2:$B$29,$A34)} -> Furniture Warehouse | C34: {=INDEX('Delivery Stops'!$D$2:$D$29,$A34)} -> 89 | D34: {=INDEX('Delivery Stops'!$E$2:$E$29,$A34)} -> 10:15 | E34: {=INDEX('Delivery Stops'!$F$2:$F$29,$A34)} -> 12:45 | F34: {=INDEX('Delivery Stops'!$G$2:$G$29,$A34)} -> 11 | G34: 0.42708333 | H34: =SUMIFS('Solver Arcs'!$F$2:$F$4061,'Solver Arcs'!$C$2:$C$4061,$A34) -> 0 | I34: =H34-1 -> -1 | J34: {=SUMPRODUCT(('Solver Arcs'!$A$2:$A$4061)*(('Solver Arcs'!$C$2:$C$4061=$A34)*('Solver Arcs'!$F$2:$F$4061)))} -> 0 | K34: 0 | L34: 0 | M34: 0 | N34: =(G34+K34/1440-D34)*1440 -> -4.7961635e-13 | O34: =(E34+L34/1440-G34)*1440 -> 150 | P34: =M34*'Cost Parameters'!$B$6+L34/60*'Cost Parameters'!$B$5 -> 0 | Q34: ='Solver Setup'!$B$9*M34-K34 -> 0 | R34: =K34-0.001*M34 -> 0
A35: 11 | B35: {=INDEX('Delivery Stops'!$B$2:$B$29,$A35)} -> Pet Hospital | C35: {=INDEX('Delivery Stops'!$D$2:$D$29,$A35)} -> 108 | D35: {=INDEX('Delivery Stops'!$E$2:$E$29,$A35)} -> 09:00 | E35: {=INDEX('Delivery Stops'!$F$2:$F$29,$A35)} -> 11:00 | F35: {=INDEX('Delivery Stops'!$G$2:$G$29,$A35)} -> 10 | G35: 0.375 | H35: =SUMIFS('Solver Arcs'!$F$2:$F$4061,'Solver Arcs'!$C$2:$C$4061,$A35) -> 0 | I35: =H35-1 -> -1 | J35: {=SUMPRODUCT(('Solver Arcs'!$A$2:$A$4061)*(('Solver Arcs'!$C$2:$C$4061=$A35)*('Solver Arcs'!$F$2:$F$4061)))} -> 0 | K35: 0 | L35: 0 | M35: 0 | N35: =(G35+K35/1440-D35)*1440 -> 0 | O35: =(E35+L35/1440-G35)*1440 -> 120 | P35: =M35*'Cost Parameters'!$B$6+L35/60*'Cost Parameters'!$B$5 -> 0 | Q35: ='Solver Setup'!$B$9*M35-K35 -> 0 | R35: =K35-0.001*M35 -> 0
A36: 12 | B36: {=INDEX('Delivery Stops'!$B$2:$B$29,$A36)} -> Tech Solutions Inc | C36: {=INDEX('Delivery Stops'!$D$2:$D$29,$A36)} -> 150 | D36: {=INDEX('Delivery Stops'!$E$2:$E$29,$A36)} -> 08:15 | E36: {=INDEX('Delivery Stops'!$F$2:$F$29,$A36)} -> 13:00 | F36: {=INDEX('Delivery Stops'!$G$2:$G$29,$A36)} -> 22 | G36: 0.34375 | H36: =SUMIFS('Solver Arcs'!$F$2:$F$4061,'Solver Arcs'!$C$2:$C$4061,$A36) -> 0 | I36: =H36-1 -> -1 | J36: {=SUMPRODUCT(('Solver Arcs'!$A$2:$A$4061)*(('Solver Arcs'!$C$2:$C$4061=$A36)*('Solver Arcs'!$F$2:$F$4061)))} -> 0 | K36: 0 | L36: 0 | M36: 0 | N36: =(G36+K36/1440-D36)*1440 -> 0 | O36: =(E36+L36/1440-G36)*1440 -> 285 | P36: =M36*'Cost Parameters'!$B$6+L36/60*'Cost Parameters'!$B$5 -> 0 | Q36: ='Solver Setup'!$B$9*M36-K36 -> 0 | R36: =K36-0.001*M36 -> 0
... A52: 28 | B52: {=INDEX('Delivery Stops'!$B$2:$B$29,$A52)} -> Food Bank | C52: {=INDEX('Delivery Stops'!$D$2:$D$29,$A52)} -> 168 | D52: {=INDEX('Delivery Stops'!$E$2:$E$29,$A52)} -> 11:45 | E52: {=INDEX('Delivery Stops'!$F$2:$F$29,$A52)} -> 14:30 | F52: {=INDEX('Delivery Stops'!$G$2:$G$29,$A52)} -> 25 | G52: 0.48958333 | H52: =SUMIFS('Solver Arcs'!$F$2:$F$4061,'Solver Arcs'!$C$2:$C$4061,$A52) -> 0 | I52: =H52-1 -> -1 | J52: {=SUMPRODUCT(('Solver Arcs'!$A$2:$A$4061)*(('Solver Arcs'!$C$2:$C$4061=$A52)*('Solver Arcs'!$F$2:$F$4061)))} -> 0 | K52: 0 | L52: 0 | M52: 0 | N52: =(G52+K52/1440-D52)*1440 -> -4.7961635e-13 | O52: =(E52+L52/1440-G52)*1440 -> 165 | P52: =M52*'Cost Parameters'!$B$6+L52/60*'Cost Parameters'!$B$5 -> 0 | Q52: ='Solver Setup'!$B$9*M52-K52 -> 0 | R52: =K52-0.001*M52 -> 0
A55: Flow Conservation Checks (each cell should be 0)
A56: Vehicle | B56: 1 | C56: 2 | D56: 3 | E56: 4 | F56: 5 | G56: 6 | H56: 7 | I56: 8 | J56: 9 | K56: 10 | L56: 11 | M56: 12 | N56: 13 | O56: 14 | P56: 15 | Q56: 16 | R56: 17 | S56: 18 | T56: 19 | U56: 20 | V56: 21 | W56: 22 | X56: 23 | Y56: 24 | Z56: 25 | AA56: 26 | AB56: 27 | AC56: 28
A57: 1 | B57: =SUMIFS('Solver Arcs'!$F$2:$F$4061,'Solver Arcs'!$A$2:$A$4061,$A57,'Solver Arcs'!$C$2:$C$4061,B$56)-SUMIFS('Solver Arcs'!$F$2:$F$4061,'Solver Arcs'!$A$2:$A$4061,$A57,'Solver Arcs'!$B$2:$B$4061,B$56) -> 0 | C57: =SUMIFS('Solver Arcs'!$F$2:$F$4061,'Solver Arcs'!$A$2:$A$4061,$A57,'Solver Arcs'!$C$2:$C$4061,C$56)-SUMIFS('Solver Arcs'!$F$2:$F$4061,'Solver Arcs'!$A$2:$A$4061,$A57,'Solver Arcs'!$B$2:$B$4061,C$56) -> 0 | D57: =SUMIFS('Solver Arcs'!$F$2:$F$4061,'Solver Arcs'!$A$2:$A$4061,$A57,'Solver Arcs'!$C$2:$C$4061,D$56)-SUMIFS('Solver Arcs'!$F$2:$F$4061,'Solver Arcs'!$A$2:$A$4061,$A57,'Solver Arcs'!$B$2:$B$4061,D$56) -> 0 | E57: =SUMIFS('Solver Arcs'!$F$2:$F$4061,'Solver Arcs'!$A$2:$A$4061,$A57,'Solver Arcs'!$C$2:$C$4061,E$56)-SUMIFS('Solver Arcs'!$F$2:$F$4061,'Solver Arcs'!$A$2:$A$4061,$A57,'Solver Arcs'!$B$2:$B$4061,E$56) -> 0 | F57: =SUMIFS('Solver Arcs'!$F$2:$F$4061,'Solver Arcs'!$A$2:$A$4061,$A57,'Solver Arcs'!$C$2:$C$4061,F$56)-SUMIFS('Solver Arcs'!$F$2:$F$4061,'Solver Arcs'!$A$2:$A$4061,$A57,'Solver Arcs'!$B$2:$B$4061,F$56) -> 0 | G57: =SUMIFS('Solver Arcs'!$F$2:$F$4061,'Solver Arcs'!$A$2:$A$4061,$A57,'Solver Arcs'!$C$2:$C$4061,G$56)-SUMIFS('Solver Arcs'!$F$2:$F$4061,'Solver Arcs'!$A$2:$A$4061,$A57,'Solver Arcs'!$B$2:$B$4061,G$56) -> 0 | H57: =SUMIFS('Solver Arcs'!$F$2:$F$4061,'Solver Arcs'!$A$2:$A$4061,$A57,'Solver Arcs'!$C$2:$C$4061,H$56)-SUMIFS('Solver Arcs'!$F$2:$F$4061,'Solver Arcs'!$A$2:$A$4061,$A57,'Solver Arcs'!$B$2:$B$4061,H$56) -> 0 | I57: =SUMIFS('Solver Arcs'!$F$2:$F$4061,'Solver Arcs'!$A$2:$A$4061,$A57,'Solver Arcs'!$C$2:$C$4061,I$56)-SUMIFS('Solver Arcs'!$F$2:$F$4061,'Solver Arcs'!$A$2:$A$4061,$A57,'Solver Arcs'!$B$2:$B$4061,I$56) -> 0 | ... AC57: =SUMIFS('Solver Arcs'!$F$2:$F$4061,'Solver Arcs'!$A$2:$A$4061,$A57,'Solver Arcs'!$C$2:$C$4061,AC$56)-SUMIFS('Solver Arcs'!$F$2:$F$4061,'Solver Arcs'!$A$2:$A$4061,$A57,'Solver Arcs'!$B$2:$B$4061,AC$56) -> 0
A58: 2 | B58: =SUMIFS('Solver Arcs'!$F$2:$F$4061,'Solver Arcs'!$A$2:$A$4061,$A58,'Solver Arcs'!$C$2:$C$4061,B$56)-SUMIFS('Solver Arcs'!$F$2:$F$4061,'Solver Arcs'!$A$2:$A$4061,$A58,'Solver Arcs'!$B$2:$B$4061,B$56) -> 0 | C58: =SUMIFS('Solver Arcs'!$F$2:$F$4061,'Solver Arcs'!$A$2:$A$4061,$A58,'Solver Arcs'!$C$2:$C$4061,C$56)-SUMIFS('Solver Arcs'!$F$2:$F$4061,'Solver Arcs'!$A$2:$A$4061,$A58,'Solver Arcs'!$B$2:$B$4061,C$56) -> 0 | D58: =SUMIFS('Solver Arcs'!$F$2:$F$4061,'Solver Arcs'!$A$2:$A$4061,$A58,'Solver Arcs'!$C$2:$C$4061,D$56)-SUMIFS('Solver Arcs'!$F$2:$F$4061,'Solver Arcs'!$A$2:$A$4061,$A58,'Solver Arcs'!$B$2:$B$4061,D$56) -> 0 | E58: =SUMIFS('Solver Arcs'!$F$2:$F$4061,'Solver Arcs'!$A$2:$A$4061,$A58,'Solver Arcs'!$C$2:$C$4061,E$56)-SUMIFS('Solver Arcs'!$F$2:$F$4061,'Solver Arcs'!$A$2:$A$4061,$A58,'Solver Arcs'!$B$2:$B$4061,E$56) -> 0 | F58: =SUMIFS('Solver Arcs'!$F$2:$F$4061,'Solver Arcs'!$A$2:$A$4061,$A58,'Solver Arcs'!$C$2:$C$4061,F$56)-SUMIFS('Solver Arcs'!$F$2:$F$4061,'Solver Arcs'!$A$2:$A$4061,$A58,'Solver Arcs'!$B$2:$B$4061,F$56) -> 0 | G58: =SUMIFS('Solver Arcs'!$F$2:$F$4061,'Solver Arcs'!$A$2:$A$4061,$A58,'Solver Arcs'!$C$2:$C$4061,G$56)-SUMIFS('Solver Arcs'!$F$2:$F$4061,'Solver Arcs'!$A$2:$A$4061,$A58,'Solver Arcs'!$B$2:$B$4061,G$56) -> 0 | H58: =SUMIFS('Solver Arcs'!$F$2:$F$4061,'Solver Arcs'!$A$2:$A$4061,$A58,'Solver Arcs'!$C$2:$C$4061,H$56)-SUMIFS('Solver Arcs'!$F$2:$F$4061,'Solver Arcs'!$A$2:$A$4061,$A58,'Solver Arcs'!$B$2:$B$4061,H$56) -> 0 | I58: =SUMIFS('Solver Arcs'!$F$2:$F$4061,'Solver Arcs'!$A$2:$A$4061,$A58,'Solver Arcs'!$C$2:$C$4061,I$56)-SUMIFS('Solver Arcs'!$F$2:$F$4061,'Solver Arcs'!$A$2:$A$4061,$A58,'Solver Arcs'!$B$2:$B$4061,I$56) -> 0 | ... AC58: =SUMIFS('Solver Arcs'!$F$2:$F$4061,'Solver Arcs'!$A$2:$A$4061,$A58,'Solver Arcs'!$C$2:$C$4061,AC$56)-SUMIFS('Solver Arcs'!$F$2:$F$4061,'Solver Arcs'!$A$2:$A$4061,$A58,'Solver Arcs'!$B$2:$B$4061,AC$56) -> 0
A59: 3 | B59: =SUMIFS('Solver Arcs'!$F$2:$F$4061,'Solver Arcs'!$A$2:$A$4061,$A59,'Solver Arcs'!$C$2:$C$4061,B$56)-SUMIFS('Solver Arcs'!$F$2:$F$4061,'Solver Arcs'!$A$2:$A$4061,$A59,'Solver Arcs'!$B$2:$B$4061,B$56) -> 0 | C59: =SUMIFS('Solver Arcs'!$F$2:$F$4061,'Solver Arcs'!$A$2:$A$4061,$A59,'Solver Arcs'!$C$2:$C$4061,C$56)-SUMIFS('Solver Arcs'!$F$2:$F$4061,'Solver Arcs'!$A$2:$A$4061,$A59,'Solver Arcs'!$B$2:$B$4061,C$56) -> 0 | D59: =SUMIFS('Solver Arcs'!$F$2:$F$4061,'Solver Arcs'!$A$2:$A$4061,$A59,'Solver Arcs'!$C$2:$C$4061,D$56)-SUMIFS('Solver Arcs'!$F$2:$F$4061,'Solver Arcs'!$A$2:$A$4061,$A59,'Solver Arcs'!$B$2:$B$4061,D$56) -> 0 | E59: =SUMIFS('Solver Arcs'!$F$2:$F$4061,'Solver Arcs'!$A$2:$A$4061,$A59,'Solver Arcs'!$C$2:$C$4061,E$56)-SUMIFS('Solver Arcs'!$F$2:$F$4061,'Solver Arcs'!$A$2:$A$4061,$A59,'Solver Arcs'!$B$2:$B$4061,E$56) -> 0 | F59: =SUMIFS('Solver Arcs'!$F$2:$F$4061,'Solver Arcs'!$A$2:$A$4061,$A59,'Solver Arcs'!$C$2:$C$4061,F$56)-SUMIFS('Solver Arcs'!$F$2:$F$4061,'Solver Arcs'!$A$2:$A$4061,$A59,'Solver Arcs'!$B$2:$B$4061,F$56) -> 0 | G59: =SUMIFS('Solver Arcs'!$F$2:$F$4061,'Solver Arcs'!$A$2:$A$4061,$A59,'Solver Arcs'!$C$2:$C$4061,G$56)-SUMIFS('Solver Arcs'!$F$2:$F$4061,'Solver Arcs'!$A$2:$A$4061,$A59,'Solver Arcs'!$B$2:$B$4061,G$56) -> 0 | H59: =SUMIFS('Solver Arcs'!$F$2:$F$4061,'Solver Arcs'!$A$2:$A$4061,$A59,'Solver Arcs'!$C$2:$C$4061,H$56)-SUMIFS('Solver Arcs'!$F$2:$F$4061,'Solver Arcs'!$A$2:$A$4061,$A59,'Solver Arcs'!$B$2:$B$4061,H$56) -> 0 | I59: =SUMIFS('Solver Arcs'!$F$2:$F$4061,'Solver Arcs'!$A$2:$A$4061,$A59,'Solver Arcs'!$C$2:$C$4061,I$56)-SUMIFS('Solver Arcs'!$F$2:$F$4061,'Solver Arcs'!$A$2:$A$4061,$A59,'Solver Arcs'!$B$2:$B$4061,I$56) -> 0 | ... AC59: =SUMIFS('Solver Arcs'!$F$2:$F$4061,'Solver Arcs'!$A$2:$A$4061,$A59,'Solver Arcs'!$C$2:$C$4061,AC$56)-SUMIFS('Solver Arcs'!$F$2:$F$4061,'Solver Arcs'!$A$2:$A$4061,$A59,'Solver Arcs'!$B$2:$B$4061,AC$56) -> 0
A60: 4 | B60: =SUMIFS('Solver Arcs'!$F$2:$F$4061,'Solver Arcs'!$A$2:$A$4061,$A60,'Solver Arcs'!$C$2:$C$4061,B$56)-SUMIFS('Solver Arcs'!$F$2:$F$4061,'Solver Arcs'!$A$2:$A$4061,$A60,'Solver Arcs'!$B$2:$B$4061,B$56) -> 0 | C60: =SUMIFS('Solver Arcs'!$F$2:$F$4061,'Solver Arcs'!$A$2:$A$4061,$A60,'Solver Arcs'!$C$2:$C$4061,C$56)-SUMIFS('Solver Arcs'!$F$2:$F$4061,'Solver Arcs'!$A$2:$A$4061,$A60,'Solver Arcs'!$B$2:$B$4061,C$56) -> 0 | D60: =SUMIFS('Solver Arcs'!$F$2:$F$4061,'Solver Arcs'!$A$2:$A$4061,$A60,'Solver Arcs'!$C$2:$C$4061,D$56)-SUMIFS('Solver Arcs'!$F$2:$F$4061,'Solver Arcs'!$A$2:$A$4061,$A60,'Solver Arcs'!$B$2:$B$4061,D$56) -> 0 | E60: =SUMIFS('Solver Arcs'!$F$2:$F$4061,'Solver Arcs'!$A$2:$A$4061,$A60,'Solver Arcs'!$C$2:$C$4061,E$56)-SUMIFS('Solver Arcs'!$F$2:$F$4061,'Solver Arcs'!$A$2:$A$4061,$A60,'Solver Arcs'!$B$2:$B$4061,E$56) -> 0 | F60: =SUMIFS('Solver Arcs'!$F$2:$F$4061,'Solver Arcs'!$A$2:$A$4061,$A60,'Solver Arcs'!$C$2:$C$4061,F$56)-SUMIFS('Solver Arcs'!$F$2:$F$4061,'Solver Arcs'!$A$2:$A$4061,$A60,'Solver Arcs'!$B$2:$B$4061,F$56) -> 0 | G60: =SUMIFS('Solver Arcs'!$F$2:$F$4061,'Solver Arcs'!$A$2:$A$4061,$A60,'Solver Arcs'!$C$2:$C$4061,G$56)-SUMIFS('Solver Arcs'!$F$2:$F$4061,'Solver Arcs'!$A$2:$A$4061,$A60,'Solver Arcs'!$B$2:$B$4061,G$56) -> 0 | H60: =SUMIFS('Solver Arcs'!$F$2:$F$4061,'Solver Arcs'!$A$2:$A$4061,$A60,'Solver Arcs'!$C$2:$C$4061,H$56)-SUMIFS('Solver Arcs'!$F$2:$F$4061,'Solver Arcs'!$A$2:$A$4061,$A60,'Solver Arcs'!$B$2:$B$4061,H$56) -> 0 | I60: =SUMIFS('Solver Arcs'!$F$2:$F$4061,'Solver Arcs'!$A$2:$A$4061,$A60,'Solver Arcs'!$C$2:$C$4061,I$56)-SUMIFS('Solver Arcs'!$F$2:$F$4061,'Solver Arcs'!$A$2:$A$4061,$A60,'Solver Arcs'!$B$2:$B$4061,I$56) -> 0 | ... AC60: =SUMIFS('Solver Arcs'!$F$2:$F$4061,'Solver Arcs'!$A$2:$A$4061,$A60,'Solver Arcs'!$C$2:$C$4061,AC$56)-SUMIFS('Solver Arcs'!$F$2:$F$4061,'Solver Arcs'!$A$2:$A$4061,$A60,'Solver Arcs'!$B$2:$B$4061,AC$56) -> 0
A61: 5 | B61: =SUMIFS('Solver Arcs'!$F$2:$F$4061,'Solver Arcs'!$A$2:$A$4061,$A61,'Solver Arcs'!$C$2:$C$4061,B$56)-SUMIFS('Solver Arcs'!$F$2:$F$4061,'Solver Arcs'!$A$2:$A$4061,$A61,'Solver Arcs'!$B$2:$B$4061,B$56) -> 0 | C61: =SUMIFS('Solver Arcs'!$F$2:$F$4061,'Solver Arcs'!$A$2:$A$4061,$A61,'Solver Arcs'!$C$2:$C$4061,C$56)-SUMIFS('Solver Arcs'!$F$2:$F$4061,'Solver Arcs'!$A$2:$A$4061,$A61,'Solver Arcs'!$B$2:$B$4061,C$56) -> 0 | D61: =SUMIFS('Solver Arcs'!$F$2:$F$4061,'Solver Arcs'!$A$2:$A$4061,$A61,'Solver Arcs'!$C$2:$C$4061,D$56)-SUMIFS('Solver Arcs'!$F$2:$F$4061,'Solver Arcs'!$A$2:$A$4061,$A61,'Solver Arcs'!$B$2:$B$4061,D$56) -> 0 | E61: =SUMIFS('Solver Arcs'!$F$2:$F$4061,'Solver Arcs'!$A$2:$A$4061,$A61,'Solver Arcs'!$C$2:$C$4061,E$56)-SUMIFS('Solver Arcs'!$F$2:$F$4061,'Solver Arcs'!$A$2:$A$4061,$A61,'Solver Arcs'!$B$2:$B$4061,E$56) -> 0 | F61: =SUMIFS('Solver Arcs'!$F$2:$F$4061,'Solver Arcs'!$A$2:$A$4061,$A61,'Solver Arcs'!$C$2:$C$4061,F$56)-SUMIFS('Solver Arcs'!$F$2:$F$4061,'Solver Arcs'!$A$2:$A$4061,$A61,'Solver Arcs'!$B$2:$B$4061,F$56) -> 0 | G61: =SUMIFS('Solver Arcs'!$F$2:$F$4061,'Solver Arcs'!$A$2:$A$4061,$A61,'Solver Arcs'!$C$2:$C$4061,G$56)-SUMIFS('Solver Arcs'!$F$2:$F$4061,'Solver Arcs'!$A$2:$A$4061,$A61,'Solver Arcs'!$B$2:$B$4061,G$56) -> 0 | H61: =SUMIFS('Solver Arcs'!$F$2:$F$4061,'Solver Arcs'!$A$2:$A$4061,$A61,'Solver Arcs'!$C$2:$C$4061,H$56)-SUMIFS('Solver Arcs'!$F$2:$F$4061,'Solver Arcs'!$A$2:$A$4061,$A61,'Solver Arcs'!$B$2:$B$4061,H$56) -> 0 | I61: =SUMIFS('Solver Arcs'!$F$2:$F$4061,'Solver Arcs'!$A$2:$A$4061,$A61,'Solver Arcs'!$C$2:$C$4061,I$56)-SUMIFS('Solver Arcs'!$F$2:$F$4061,'Solver Arcs'!$A$2:$A$4061,$A61,'Solver Arcs'!$B$2:$B$4061,I$56) -> 0 | ... AC61: =SUMIFS('Solver Arcs'!$F$2:$F$4061,'Solver Arcs'!$A$2:$A$4061,$A61,'Solver Arcs'!$C$2:$C$4061,AC$56)-SUMIFS('Solver Arcs'!$F$2:$F$4061,'Solver Arcs'!$A$2:$A$4061,$A61,'Solver Arcs'!$B$2:$B$4061,AC$56) -> 0
A64: Solver Constraint Map
...

Sheet Solver Arcs
A1: Vehicle_ID | B1: From_Node | C1: To_Node | D1: From_Name | E1: To_Name | F1: Use_Arc | G1: Distance_mi | H1: Travel_Min | I1: Variable_Cost | J1: To_Demand_kg | K1: Arc_Cost_Selected | L1: Distance_Selected | M1: Drive_Min_Selected | N1: Demand_Selected | O1: Time_Continuity_Slack_min
A2: 1 | B2: 0 | C2: 1 | D2: {=IF(B2=0,"Depot",INDEX('Delivery Stops'!$B$2:$B$29,B2))} -> Depot | E2: {=IF(C2=0,"Depot",INDEX('Delivery Stops'!$B$2:$B$29,C2))} -> Pet Hospital | F2: 0 | G2: {=INDEX('Distance Matrix (miles)'!$B$2:$AD$30,B2+1,C2+1)} -> 24.68 | H2: {=INDEX('Travel Time Matrix (min)'!$B$2:$AD$30,B2+1,C2+1)} -> 37 | I2: {=G2*(INDEX('Vehicle Fleet'!$D$2:$D$6,A2)+'Cost Parameters'!$B$2*'Cost Parameters'!$B$3)} -> 21.135952 | J2: {=IF(C2=0,0,INDEX('Delivery Stops'!$D$2:$D$29,C2))} -> 204 | K2: =F2*I2 -> 0 | L2: =F2*G2 -> 0 | M2: =F2*H2 -> 0 | N2: =F2*J2 -> 0 | O2: {=((IF(C2=0,INDEX('Solver Setup'!$M$15:$M$19,A2),INDEX('Solver Setup'!$G$25:$G$52,C2))-IF(B2=0,INDEX('Solver Setup'!$L$15:$L$19,A2),INDEX('Solver Setup'!$G$25:$G$52,B2)))*1440-IF(B2=0,0,INDEX('Solver Setup'!$F$25:$F$52,B2))-H2+'Solver Setup'!$B$9*(1-F2))} -> 1913
A3: 1 | B3: 0 | C3: 2 | D3: {=IF(B3=0,"Depot",INDEX('Delivery Stops'!$B$2:$B$29,B3))} -> Depot | E3: {=IF(C3=0,"Depot",INDEX('Delivery Stops'!$B$2:$B$29,C3))} -> Community Pharmacy | F3: 0 | G3: {=INDEX('Distance Matrix (miles)'!$B$2:$AD$30,B3+1,C3+1)} -> 2.8 | H3: {=INDEX('Travel Time Matrix (min)'!$B$2:$AD$30,B3+1,C3+1)} -> 4.2 | I3: {=G3*(INDEX('Vehicle Fleet'!$D$2:$D$6,A3)+'Cost Parameters'!$B$2*'Cost Parameters'!$B$3)} -> 2.39792 | J3: {=IF(C3=0,0,INDEX('Delivery Stops'!$D$2:$D$29,C3))} -> 240 | K3: =F3*I3 -> 0 | L3: =F3*G3 -> 0 | M3: =F3*H3 -> 0 | N3: =F3*J3 -> 0 | O3: {=((IF(C3=0,INDEX('Solver Setup'!$M$15:$M$19,A3),INDEX('Solver Setup'!$G$25:$G$52,C3))-IF(B3=0,INDEX('Solver Setup'!$L$15:$L$19,A3),INDEX('Solver Setup'!$G$25:$G$52,B3)))*1440-IF(B3=0,0,INDEX('Solver Setup'!$F$25:$F$52,B3))-H3+'Solver Setup'!$B$9*(1-F3))} -> 2185.8
A4: 1 | B4: 0 | C4: 3 | D4: {=IF(B4=0,"Depot",INDEX('Delivery Stops'!$B$2:$B$29,B4))} -> Depot | E4: {=IF(C4=0,"Depot",INDEX('Delivery Stops'!$B$2:$B$29,C4))} -> Redstone Medical Center | F4: 0 | G4: {=INDEX('Distance Matrix (miles)'!$B$2:$AD$30,B4+1,C4+1)} -> 19.3 | H4: {=INDEX('Travel Time Matrix (min)'!$B$2:$AD$30,B4+1,C4+1)} -> 29 | I4: {=G4*(INDEX('Vehicle Fleet'!$D$2:$D$6,A4)+'Cost Parameters'!$B$2*'Cost Parameters'!$B$3)} -> 16.52852 | J4: {=IF(C4=0,0,INDEX('Delivery Stops'!$D$2:$D$29,C4))} -> 183 | K4: =F4*I4 -> 0 | L4: =F4*G4 -> 0 | M4: =F4*H4 -> 0 | N4: =F4*J4 -> 0 | O4: {=((IF(C4=0,INDEX('Solver Setup'!$M$15:$M$19,A4),INDEX('Solver Setup'!$G$25:$G$52,C4))-IF(B4=0,INDEX('Solver Setup'!$L$15:$L$19,A4),INDEX('Solver Setup'!$G$25:$G$52,B4)))*1440-IF(B4=0,0,INDEX('Solver Setup'!$F$25:$F$52,B4))-H4+'Solver Setup'!$B$9*(1-F4))} -> 2176
A5: 1 | B5: 0 | C5: 4 | D5: {=IF(B5=0,"Depot",INDEX('Delivery Stops'!$B$2:$B$29,B5))} -> Depot | E5: {=IF(C5=0,"Depot",INDEX('Delivery Stops'!$B$2:$B$29,C5))} -> Furniture Warehouse | F5: 0 | G5: {=INDEX('Distance Matrix (miles)'!$B$2:$AD$30,B5+1,C5+1)} -> 8.46 | H5: {=INDEX('Travel Time Matrix (min)'!$B$2:$AD$30,B5+1,C5+1)} -> 12.7 | I5: {=G5*(INDEX('Vehicle Fleet'!$D$2:$D$6,A5)+'Cost Parameters'!$B$2*'Cost Parameters'!$B$3)} -> 7.245144 | J5: {=IF(C5=0,0,INDEX('Delivery Stops'!$D$2:$D$29,C5))} -> 186 | K5: =F5*I5 -> 0 | L5: =F5*G5 -> 0 | M5: =F5*H5 -> 0 | N5: =F5*J5 -> 0 | O5: {=((IF(C5=0,INDEX('Solver Setup'!$M$15:$M$19,A5),INDEX('Solver Setup'!$G$25:$G$52,C5))-IF(B5=0,INDEX('Solver Setup'!$L$15:$L$19,A5),INDEX('Solver Setup'!$G$25:$G$52,B5)))*1440-IF(B5=0,0,INDEX('Solver Setup'!$F$25:$F$52,B5))-H5+'Solver Setup'!$B$9*(1-F5))} -> 1922.3
A6: 1 | B6: 0 | C6: 5 | D6: {=IF(B6=0,"Depot",INDEX('Delivery Stops'!$B$2:$B$29,B6))} -> Depot | E6: {=IF(C6=0,"Depot",INDEX('Delivery Stops'!$B$2:$B$29,C6))} -> Construction Supply | F6: 0 | G6: {=INDEX('Distance Matrix (miles)'!$B$2:$AD$30,B6+1,C6+1)} -> 16.04 | H6: {=INDEX('Travel Time Matrix (min)'!$B$2:$AD$30,B6+1,C6+1)} -> 24.1 | I6: {=G6*(INDEX('Vehicle Fleet'!$D$2:$D$6,A6)+'Cost Parameters'!$B$2*'Cost Parameters'!$B$3)} -> 13.736656 | J6: {=IF(C6=0,0,INDEX('Delivery Stops'!$D$2:$D$29,C6))} -> 201 | K6: =F6*I6 -> 0 | L6: =F6*G6 -> 0 | M6: =F6*H6 -> 0 | N6: =F6*J6 -> 0 | O6: {=((IF(C6=0,INDEX('Solver Setup'!$M$15:$M$19,A6),INDEX('Solver Setup'!$G$25:$G$52,C6))-IF(B6=0,INDEX('Solver Setup'!$L$15:$L$19,A6),INDEX('Solver Setup'!$G$25:$G$52,B6)))*1440-IF(B6=0,0,INDEX('Solver Setup'!$F$25:$F$52,B6))-H6+'Solver Setup'!$B$9*(1-F6))} -> 2120.9
A7: 1 | B7: 0 | C7: 6 | D7: {=IF(B7=0,"Depot",INDEX('Delivery Stops'!$B$2:$B$29,B7))} -> Depot | E7: {=IF(C7=0,"Depot",INDEX('Delivery Stops'!$B$2:$B$29,C7))} -> Farm Supply | F7: 0 | G7: {=INDEX('Distance Matrix (miles)'!$B$2:$AD$30,B7+1,C7+1)} -> 4.67 | H7: {=INDEX('Travel Time Matrix (min)'!$B$2:$AD$30,B7+1,C7+1)} -> 7 | I7: {=G7*(INDEX('Vehicle Fleet'!$D$2:$D$6,A7)+'Cost Parameters'!$B$2*'Cost Parameters'!$B$3)} -> 3.999388 | J7: {=IF(C7=0,0,INDEX('Delivery Stops'!$D$2:$D$29,C7))} -> 162 | K7: =F7*I7 -> 0 | L7: =F7*G7 -> 0 | M7: =F7*H7 -> 0 | N7: =F7*J7 -> 0 | O7: {=((IF(C7=0,INDEX('Solver Setup'!$M$15:$M$19,A7),INDEX('Solver Setup'!$G$25:$G$52,C7))-IF(B7=0,INDEX('Solver Setup'!$L$15:$L$19,A7),INDEX('Solver Setup'!$G$25:$G$52,B7)))*1440-IF(B7=0,0,INDEX('Solver Setup'!$F$25:$F$52,B7))-H7+'Solver Setup'!$B$9*(1-F7))} -> 2243
A8: 1 | B8: 0 | C8: 7 | D8: {=IF(B8=0,"Depot",INDEX('Delivery Stops'!$B$2:$B$29,B8))} -> Depot | E8: {=IF(C8=0,"Depot",INDEX('Delivery Stops'!$B$2:$B$29,C8))} -> Fish Market | F8: 0 | G8: {=INDEX('Distance Matrix (miles)'!$B$2:$AD$30,B8+1,C8+1)} -> 10.63 | H8: {=INDEX('Travel Time Matrix (min)'!$B$2:$AD$30,B8+1,C8+1)} -> 15.9 | I8: {=G8*(INDEX('Vehicle Fleet'!$D$2:$D$6,A8)+'Cost Parameters'!$B$2*'Cost Parameters'!$B$3)} -> 9.103532 | J8: {=IF(C8=0,0,INDEX('Delivery Stops'!$D$2:$D$29,C8))} -> 133 | K8: =F8*I8 -> 0 | L8: =F8*G8 -> 0 | M8: =F8*H8 -> 0 | N8: =F8*J8 -> 0 | O8: {=((IF(C8=0,INDEX('Solver Setup'!$M$15:$M$19,A8),INDEX('Solver Setup'!$G$25:$G$52,C8))-IF(B8=0,INDEX('Solver Setup'!$L$15:$L$19,A8),INDEX('Solver Setup'!$G$25:$G$52,B8)))*1440-IF(B8=0,0,INDEX('Solver Setup'!$F$25:$F$52,B8))-H8+'Solver Setup'!$B$9*(1-F8))} -> 2099.1
A9: 1 | B9: 0 | C9: 8 | D9: {=IF(B9=0,"Depot",INDEX('Delivery Stops'!$B$2:$B$29,B9))} -> Depot | E9: {=IF(C9=0,"Depot",INDEX('Delivery Stops'!$B$2:$B$29,C9))} -> Swimming Pool Supply | F9: 0 | G9: {=INDEX('Distance Matrix (miles)'!$B$2:$AD$30,B9+1,C9+1)} -> 25.87 | H9: {=INDEX('Travel Time Matrix (min)'!$B$2:$AD$30,B9+1,C9+1)} -> 38.8 | I9: {=G9*(INDEX('Vehicle Fleet'!$D$2:$D$6,A9)+'Cost Parameters'!$B$2*'Cost Parameters'!$B$3)} -> 22.155068 | J9: {=IF(C9=0,0,INDEX('Delivery Stops'!$D$2:$D$29,C9))} -> 285 | K9: =F9*I9 -> 0 | L9: =F9*G9 -> 0 | M9: =F9*H9 -> 0 | N9: =F9*J9 -> 0 | O9: {=((IF(C9=0,INDEX('Solver Setup'!$M$15:$M$19,A9),INDEX('Solver Setup'!$G$25:$G$52,C9))-IF(B9=0,INDEX('Solver Setup'!$L$15:$L$19,A9),INDEX('Solver Setup'!$G$25:$G$52,B9)))*1440-IF(B9=0,0,INDEX('Solver Setup'!$F$25:$F$52,B9))-H9+'Solver Setup'!$B$9*(1-F9))} -> 2286.2
A10: 1 | B10: 0 | C10: 9 | D10: {=IF(B10=0,"Depot",INDEX('Delivery Stops'!$B$2:$B$29,B10))} -> Depot | E10: {=IF(C10=0,"Depot",INDEX('Delivery Stops'!$B$2:$B$29,C10))} -> Dry Cleaners | F10: 0 | G10: {=INDEX('Distance Matrix (miles)'!$B$2:$AD$30,B10+1,C10+1)} -> 14.44 | H10: {=INDEX('Travel Time Matrix (min)'!$B$2:$AD$30,B10+1,C10+1)} -> 21.7 | I10: {=G10*(INDEX('Vehicle Fleet'!$D$2:$D$6,A10)+'Cost Parameters'!$B$2*'Cost Parameters'!$B$3)} -> 12.366416 | J10: {=IF(C10=0,0,INDEX('Delivery Stops'!$D$2:$D$29,C10))} -> 24 | K10: =F10*I10 -> 0 | L10: =F10*G10 -> 0 | M10: =F10*H10 -> 0 | N10: =F10*J10 -> 0 | O10: {=((IF(C10=0,INDEX('Solver Setup'!$M$15:$M$19,A10),INDEX('Solver Setup'!$G$25:$G$52,C10))-IF(B10=0,INDEX('Solver Setup'!$L$15:$L$19,A10),INDEX('Solver Setup'!$G$25:$G$52,B10)))*1440-IF(B10=0,0,INDEX('Solver Setup'!$F$25:$F$52,B10))-H10+'Solver Setup'!$B$9*(1-F10))} -> 1958.3
A11: 1 | B11: 0 | C11: 10 | D11: {=IF(B11=0,"Depot",INDEX('Delivery Stops'!$B$2:$B$29,B11))} -> Depot | E11: {=IF(C11=0,"Depot",INDEX('Delivery Stops'!$B$2:$B$29,C11))} -> Furniture Warehouse | F11: 0 | G11: {=INDEX('Distance Matrix (miles)'!$B$2:$AD$30,B11+1,C11+1)} -> 7.45 | H11: {=INDEX('Travel Time Matrix (min)'!$B$2:$AD$30,B11+1,C11+1)} -> 11.2 | I11: {=G11*(INDEX('Vehicle Fleet'!$D$2:$D$6,A11)+'Cost Parameters'!$B$2*'Cost Parameters'!$B$3)} -> 6.38018 | J11: {=IF(C11=0,0,INDEX('Delivery Stops'!$D$2:$D$29,C11))} -> 89 | K11: =F11*I11 -> 0 | L11: =F11*G11 -> 0 | M11: =F11*H11 -> 0 | N11: =F11*J11 -> 0 | O11: {=((IF(C11=0,INDEX('Solver Setup'!$M$15:$M$19,A11),INDEX('Solver Setup'!$G$25:$G$52,C11))-IF(B11=0,INDEX('Solver Setup'!$L$15:$L$19,A11),INDEX('Solver Setup'!$G$25:$G$52,B11)))*1440-IF(B11=0,0,INDEX('Solver Setup'!$F$25:$F$52,B11))-H11+'Solver Setup'!$B$9*(1-F11))} -> 2043.8
A12: 1 | B12: 0 | C12: 11 | D12: {=IF(B12=0,"Depot",INDEX('Delivery Stops'!$B$2:$B$29,B12))} -> Depot | E12: {=IF(C12=0,"Depot",INDEX('Delivery Stops'!$B$2:$B$29,C12))} -> Pet Hospital | F12: 0 | G12: {=INDEX('Distance Matrix (miles)'!$B$2:$AD$30,B12+1,C12+1)} -> 1.35 | H12: {=INDEX('Travel Time Matrix (min)'!$B$2:$AD$30,B12+1,C12+1)} -> 2 | I12: {=G12*(INDEX('Vehicle Fleet'!$D$2:$D$6,A12)+'Cost Parameters'!$B$2*'Cost Parameters'!$B$3)} -> 1.15614 | J12: {=IF(C12=0,0,INDEX('Delivery Stops'!$D$2:$D$29,C12))} -> 108 | K12: =F12*I12 -> 0 | L12: =F12*G12 -> 0 | M12: =F12*H12 -> 0 | N12: =F12*J12 -> 0 | O12: {=((IF(C12=0,INDEX('Solver Setup'!$M$15:$M$19,A12),INDEX('Solver Setup'!$G$25:$G$52,C12))-IF(B12=0,INDEX('Solver Setup'!$L$15:$L$19,A12),INDEX('Solver Setup'!$G$25:$G$52,B12)))*1440-IF(B12=0,0,INDEX('Solver Setup'!$F$25:$F$52,B12))-H12+'Solver Setup'!$B$9*(1-F12))} -> 1978
A13: 1 | B13: 0 | C13: 12 | D13: {=IF(B13=0,"Depot",INDEX('Delivery Stops'!$B$2:$B$29,B13))} -> Depot | E13: {=IF(C13=0,"Depot",INDEX('Delivery Stops'!$B$2:$B$29,C13))} -> Tech Solutions Inc | F13: 0 | G13: {=INDEX('Distance Matrix (miles)'!$B$2:$AD$30,B13+1,C13+1)} -> 8.72 | H13: {=INDEX('Travel Time Matrix (min)'!$B$2:$AD$30,B13+1,C13+1)} -> 13.1 | I13: {=G13*(INDEX('Vehicle Fleet'!$D$2:$D$6,A13)+'Cost Parameters'!$B$2*'Cost Parameters'!$B$3)} -> 7.467808 | J13: {=IF(C13=0,0,INDEX('Delivery Stops'!$D$2:$D$29,C13))} -> 150 | K13: =F13*I13 -> 0 | L13: =F13*G13 -> 0 | M13: =F13*H13 -> 0 | N13: =F13*J13 -> 0 | O13: {=((IF(C13=0,INDEX('Solver Setup'!$M$15:$M$19,A13),INDEX('Solver Setup'!$G$25:$G$52,C13))-IF(B13=0,INDEX('Solver Setup'!$L$15:$L$19,A13),INDEX('Solver Setup'!$G$25:$G$52,B13)))*1440-IF(B13=0,0,INDEX('Solver Setup'!$F$25:$F$52,B13))-H13+'Solver Setup'!$B$9*(1-F13))} -> 1921.9
... A4061: 5 | B4061: 28 | C4061: 27 | D4061: {=IF(B4061=0,"Depot",INDEX('Delivery Stops'!$B$2:$B$29,B4061))} -> Food Bank | E4061: {=IF(C4061=0,"Depot",INDEX('Delivery Stops'!$B$2:$B$29,C4061))} -> Redstone Elementary School | F4061: 0 | G4061: {=INDEX('Distance Matrix (miles)'!$B$2:$AD$30,B4061+1,C4061+1)} -> 19.99 | H4061: {=INDEX('Travel Time Matrix (min)'!$B$2:$AD$30,B4061+1,C4061+1)} -> 30 | I4061: {=G4061*(INDEX('Vehicle Fleet'!$D$2:$D$6,A4061)+'Cost Parameters'!$B$2*'Cost Parameters'!$B$3)} -> 31.112436 | J4061: {=IF(C4061=0,0,INDEX('Delivery Stops'!$D$2:$D$29,C4061))} -> 61 | K4061: =F4061*I4061 -> 0 | L4061: =F4061*G4061 -> 0 | M4061: =F4061*H4061 -> 0 | N4061: =F4061*J4061 -> 0 | O4061: {=((IF(C4061=0,INDEX('Solver Setup'!$M$15:$M$19,A4061),INDEX('Solver Setup'!$G$25:$G$52,C4061))-IF(B4061=0,INDEX('Solver Setup'!$L$15:$L$19,A4061),INDEX('Solver Setup'!$G$25:$G$52,B4061)))*1440-IF(B4061=0,0,INDEX('Solver Setup'!$F$25:$F$52,B4061))-H4061+'Solver Setup'!$B$9*(1-F4061))} -> 1385
